Workbook

Sheet data
A1: n° | B1: Marseille (x) | C1: Futur (y) | D1: Table | E1: Tour | F1: remarque | G1: idée | H1: prompt original | I1: image (URL) | J1: model
A2: 2 | B2: 6 | C2: 6.5 | D2: A | E2: 1 | F2: a copier-coller à chaque atelier | G2: École flottante du Vieux-Port : Dans le Vieux-Port de Marseille, une école flottante construite sur des barges solaires accueille élèves et professeurs. Entourés d’eau turquoise et de forêts urbaines sur les quais, les enfants rejoignent la classe en navette amphibie et étudient en oscillant doucement au rythme des vagues, symbole d’une adaptation sereine à la montée des eaux (inspiré par un imaginaire Cli-fi optimiste). | H2: Marseille, 2050. A floating classroom barge rocks gently in the Vieux-Port. The science teacher crouches beside students measuring water salinity, reflections of hulls trembling on their faces. Seagulls circle above cranes and masts. The air smells of salt and algae, the sunlight harsh but alive. Photorealistic street-photo look, high contrast, maritime textures, candid composition. | I2: https://drive.google.com/file/d/1fhbLgvg0hsz4TNLeXeSF0mFWcvDZddGd/view?usp=drive_link | J2: flux dev
A3: 5 | B3: 6.5 | C3: 10 | D3: A | E3: 1 | F3: groupe n'a pas changé entre T1, T2 et T3... probable qu'ils se soient débarrassés de l'exercice | G3: Classes mobiles modulaires : Des salles de classe modulaires montées sur des véhicules autonomes se déplacent à travers Marseille. Un matin, une bulle de classe s'installe sur une placette du Panier, l’après-midi au pied des tours de la Joliette : ces pods high-tech offrent un enseignement de proximité, transformant n’importe quel coin de rue en espace d’apprentissage lorsqu’ils se déploient (inspiré par la design fiction futuriste). | H3: Marseille, 2050. In a narrow Le Panier square, a mobile classroom pod glows softly between graffiti-covered walls. Students gather around an AR timeline projected on the cobblestones. The teacher stands mid-frame, light bouncing off her tablet onto the stone. Shadows, scooters, and hanging cables frame the scene — raw and real, street-photo realism, golden late afternoon. | I3: https://drive.google.com/file/d/1W7Korom927gbc6HmwCbPUpS8vYgldZiY/view?usp=drive_link | J3: flux dev
A4: 6 | B4: 9.5 | C4: 6 | D4: A | E4: 1 | G4: École en forêt urbaine : En 2050, une pinède des Calanques abrite une école en plein air où les cours se font sous les pins parasols. Les enfants assis en cercle sur des troncs d’arbre étudient la biologie en observant la faune et la flore locales, tandis que des tablettes alimentées au solaire projettent des hologrammes éducatifs entre les branches (inspiré par le courant Solarpunk). | H4: Marseille, 2050. Beneath the pines of Sormiou, an ecology class kneels in the dry earth, magnifying wild plants. The teacher’s hands are dusty, a notebook half-filled with sketches. The sea glimmers below the limestone cliffs, the mistral lifting hair and paper. Photorealistic, natural light documentary look, deep textures of stone, sweat, and learning. | I4: https://drive.google.com/file/d/1nBi-M5nL6M1oSQo5aEMRJAYjwYr5kWBU/view?usp=drive_link | J4: flux dev
A5: 13 | B5: 4 | C5: 10 | D5: A | E5: 1 | G5: Dômes solaires climatisés : Les cours d'école se dotent de dômes transparents à énergie solaire pour se protéger des aléas climatiques. À Marseille, ces verrières high-tech filtrent la brûlure du soleil d'été et atténuent le Mistral tout en laissant passer la lumière. Sous le dôme d’une école du Prado, les enfants peuvent jardiner ou faire du sport toute l’année dans un microclimat idéal (inspiré par le courant Solarpunk). | H5: Marseille, 2050. Midday in the courtyard of a Prado elementary school, where a vast orange solar dome glows softly above hundreds of playing children. Its curved panels, made from translucent photovoltaic glass, filter the fierce Mediterranean sun into a warm amber light that bathes the space in golden tones. Outside, the city swelters under a white, blinding sky — heat shimmering over rooftops and empty streets — but inside the dome, the air moves gently through open vents, fresh and breathable. Children of all backgrounds race across the polished playground, their laughter echoing under the curved canopy. A physics teacher with freckled skin kneels beside a small airflow turbine, showing a curious group how it transforms heat into energy. Nearby, others play football, climb green-framed structures, or water plants in raised garden beds. Light flickers on faces, shoes, and leaves, the color of honey and wind. Photorealistic handheld 28mm, cinematic Solarpunk realism, vibrant contrast between the blinding exterior and the glowing orange interior — Marseille’s schools reborn as luminous shelters of learning and play. | I5: https://drive.google.com/file/d/1VLU2LS8Orkv7SZDBn9xJgcUVGmFB9OAH/view?usp=drive_link | J5: flux dev
A6: 25 | B6: 1 | C6: 10 | D6: A | E6: 1 | G6: Connaissances téléchargées : Grâce à un implant neuronal, des élèves peuvent télécharger directement dans leur cerveau certaines connaissances. En quelques heures, un lycéen marseillais acquiert ainsi les bases d’une nouvelle langue ou d’un instrument de musique, simplement en transférant des données depuis une bibliothèque numérique. L’efficacité est prodigieuse, mais ces "étudiants augmentés" suscitent le débat : que reste-t-il de l’expérience et de l’esprit critique acquis par l'effort, si apprendre devient aussi facile que charger un fichier ? (inspiré par la science-fiction transhumaniste). | H6: Marseille, 2050. In Parc Longchamp, beneath tall plane trees swaying in the morning breeze, a French class gathers on the grass in a wide open circle. At the center, a student reader holds an open book, her silver audio headset glowing with soft blue light as she begins to read aloud. Around her, classmates of different backgrounds — each wearing the same sleek headset — sit facing one another, forming a luminous ring of connection. From every headset, thin arcs of light extend and intertwine through the air, linking listener to listener in a visible web of shared sound. Some students smile, others exchange glances, following the rhythm of the reader’s voice that flows between them like electricity. The teacher, standing just beyond the circle, observes with quiet satisfaction, her headset gently pulsing in sync with the group. The warm Mediterranean light filters through the leaves, flickering over faces, pages, and the intricate weave of glowing threads. Photorealistic handheld 35mm, cinematic composition, warm golden tones, tactile realism of grass, light, and technology — a living network of voices and connection in Marseille’s park classroom of the future. | I6: https://drive.google.com/file/d/1XuZEEiIwpk_lMssqM0GRrA2NgWiRxgkw/view?usp=drive_link | J6: flux dev
A7: 36 | B7: 5.5 | C7: 8 | D7: A | E7: 1 | G7: Manuels holographiques : Les livres scolaires physiques ont quasiment disparu au profit de manuels holographiques et interactifs. En cours de sciences, un professeur fait apparaître au centre de la classe un cœur humain en 3D qui bat et réagit aux questions posées à voix haute. En littérature, les scènes d’un roman prennent vie en réalité augmentée autour des élèves. Ces supports immersifs transforment les apprentissages en expériences vivantes (inspiré par la science-fiction d’anticipation). | H7: Marseille, 2050. In a biology lab with open windows to the sea, a teacher with short locs adjusts a holographic heart model rotating mid-air. Students of mixed origins trace arteries with styluses. Red light pulses through the hologram, reflecting on their eyes and glass benches. Photorealistic cinematic glow, color contrast of blue daylight and red holographic tone. | I7: https://drive.google.com/file/d/13UquZY7-PvjzHDgsgE8YZgIgGEjT8mGr/view?usp=drive_link | J7: flux dev
A8: 41 | B8: 8 | C8: 6 | D8: A | E8: 1 | G8: Projets citoyens au programme : Plutôt que de simples devoirs, les lycéens marseillais doivent réaliser chaque trimestre un projet concret pour leur quartier. L’un a coordonné la création d’un jardin partagé dans une friche des quartiers Nord, un autre a développé une appli pour recenser les fontaines d’eau potable de la ville. Ces projets, évalués par les habitants et les profs, remplacent les notes classiques et donnent du sens aux apprentissages théoriques (inspiré par le courant Hopepunk). | H8: Marseille, 2050. In a lush community garden in northern Marseille, a woman of Cape Verdean descent kneels beside a patch of rich soil, showing a group of children how to plant a seed. Her hands move slowly and deliberately, pressing the earth around the tiny sprout as the children — boys and girls of mixed backgrounds — watch closely, their faces lit by the low golden sun. Some hold small biodegradable pots, others dig with their fingers, laughing softly as they imitate her gesture. Around them, raised beds overflow with vegetables and flowers, and a solar-powered irrigation system hums gently in the background. The atmosphere is calm, purposeful, and full of warmth — learning through doing, rooted in care for the earth. Photorealistic cinematic realism, handheld 35mm, golden hour light, natural textures of soil, skin, and green life — a Marseille garden classroom where education grows from the ground up. | I8: https://drive.google.com/file/d/12Mz9KeJxCPlM2qz67Hmw9IBM49T5QKa3/view?usp=drive_link | J8: flux dev
A9: 45 | B9: 9.5 | C9: 6.5 | D9: A | E9: 1 | G9: Plus d’examens, place au portfolio : Le bachotage appartient au passé. En 2050, les élèves marseillais présentent en fin d’année un portfolio de leurs projets et compétences devant un jury composé d’enseignants mais aussi de parents et de membres du quartier. Une élève expose par exemple son court-métrage réalisé en cours de langue, un autre démontre le robot qu’il a fabriqué en atelier. Cette évaluation globale sur travaux concrets remplace les examens traditionnels, jugés trop déconnectés du réel (inspiré par une utopie éducative). | H9: Marseille, 2050. In the Vieux-Port, a project expo buzzes: a teacher with silver dreadlocks reviews student prototypes. One team of three — one pale, one veiled, one dark-skinned — presents a floating desalination unit. The teacher smiles, wind tugs at plans. Sunlight flashes off chrome and sea. Cinematic handheld realism, warm Marseille palette. | I9: https://drive.google.com/file/d/10EYeHwHh92QJU5CjvJvcN-1CluGq6eok/view?usp=drive_link | J9: flux dev
A10: 49 | B10: 9.5 | C10: 9 | D10: A | E10: 1 | G10: Service civique intégré : Au lycée, chaque élève doit consacrer une partie de son année à un projet solidaire encadré par l’école. Certains choisissent de participer à la reforestation du massif de la Sainte-Baume après des incendies, d’autres d’organiser des maraudes technologiques où ils réparent des téléphones pour des sans-abris afin de les reconnecter. Cette expérience de terrain compte dans leur formation et développe le sens de l’initiative et de la citoyenneté (inspiré par le courant Hopepunk). | H10: Marseille, 2050. On the shore of Les Catalans beach, a group of high school students in bright orange rescue vests kneels around a teacher demonstrating how to save a drowning person. A mannequin lies half in the water, waves lapping gently against it as the teacher shows how to position the head and start chest compressions. One student with braided hair counts aloud, another boy in shorts and a rash guard holds a flotation device, ready to practice. In the background, more students wait their turn beside a rescue drone hovering above the sea, scanning for movement. The sun glows high, the water sparkles, and the air hums with concentration and sea breeze. Photorealistic cinematic realism, handheld 35mm, Mediterranean tones, sharp contrast of orange vests against blue water — Marseille’s civic education grounded in real-life lifesaving. | I10: https://drive.google.com/file/d/1N40HKePFubgCfauGPpbQdTBSNu7MDVap/view?usp=drive_link | J10: flux dev
A11: 66 | B11: 1 | C11: 10 | D11: A | E11: 1 | G11: Crèche auto-gérée high-tech : Dans un immeuble du quartier Saint-Barnabé, les jeunes parents ont monté une crèche partagée. Chaque jour, deux parents volontaires gardent l’ensemble des bambins dans une salle commune colorée, pendant que les autres travaillent. Une application IA organise le planning équitablement selon les disponibilités de chacun. Un petit robot nounou aide à chauffer les biberons et à bercer les bébés, tandis qu’un voisin retraité vient faire la sieste contée. Cette solidarité 2.0 allège les frais de garde et crée du lien dans l’immeuble (inspiré par le courant Hopepunk). | H11: Marseille, 2050. Inside a bright shared nursery in a renovated apartment building at Saint-Barnabé, the room is filled with the joyful energy of baby boys and girls playing together on colorful foam mats scattered with recycled-wood toys and softly glowing cubes. Warm Mediterranean light pours through tall windows, illuminating pastel murals of trees, clouds, and sea animals. At the center, a young mother of Asian descent and a tall dark-skinned father gently guide a group of toddlers stacking luminous blocks that light up at every touch. In one corner, an elderly man with silver hair and gentle eyes sits in a small chair, reading a story from a digital picture book to a baby girl on his knee, while a nearby boy leans close to watch the moving illustrations. A small round nursery robot rocks a cradle softly, humming as it warms a bottle. On the wall, a holographic schedule panel glows with the parents’ volunteer shifts. The air hums with laughter, color, and sunlight — a Marseille nursery where families, technology, and care blend seamlessly into daily life. Photorealistic cinematic realism, handheld 35mm, warm daylight tones, tactile detail of skin, wood, and fabric, hopeful Mediterranean atmosphere. | I11: https://drive.google.com/file/d/18b86xwvvPn3hBm81SeeCNQlWYo-lJonE/view?usp=drive_link | J11: flux dev
A12: 74 | B12: 6 | C12: 6 | D12: A | E12: 1 | G12: Campus à la carte : Les lycéens ne sont plus rattachés à un seul établissement fixe. Une plateforme commune aux écoles de Marseille permet de suivre des cours spécifiques dans l’établissement qui excelle dans la matière. Le matin, un élève passionné d’astronomie va au lycée Saint-Exupéry pour son planétarium, l’après-midi il rejoint Montgrand pour un atelier de haute couture, et termine la journée à la fac de Luminy pour un séminaire d’écologie. Des navettes électriques autonomes relient en permanence ces pôles de spécialité. L’éducation devient un parcours fluide à l’échelle de la métropole (inspiré par la prospective éducative). | H12: Marseille, 2050. On a platform at Saint-Charles, a teacher with light brown skin guides students onto an autonomous shuttle labeled “Campus Line.” A boy waves through the glass; the teacher laughs. Afternoon heat shimmers on rails, pigeons scatter at the edge of the frame. Photorealistic handheld realism, crisp focus, Marseille’s kinetic calm. | I12: https://drive.google.com/file/d/1rALogf0z4JQyz6qtTe8D_8WK-beWdAeg/view?usp=drive_link | J12: flux dev
A13: 81 | B13: 5.5 | C13: 10 | D13: A | E13: 1 | G13: École hackée underground : Dans les sous-sols d’une usine abandonnée de la zone de la Joliette, un collectif de jeunes hackers a créé sa propre école officieuse. L’ambiance y est cyberpunk : néons colorés, murs couverts de code binaire en graffiti et écrans recyclés branchés sur le réseau. On y enseigne le code, la cybersécurité et la fabrication d’objets libres en dehors de tout cadre officiel. Les connaissances circulent librement, et les membres du collectif piratent les bases de données académiques pour démocratiser le savoir, dans un esprit rebelle mais solidaire (inspiré par le courant Cyberpunk). | H13: Marseille, 2050. In a dimly lit La Joliette basement, the air hums softly with the rhythm of typing. At the front, a young woman wearing a light-colored veil works intently, her face illuminated by the blue glow of her screen as lines of code scroll in reflection. Around her, other students — men and women without veils — sit at scattered desks, focused, their faces half-lit by flickering monitors. At the back of the room, a computer science teacher of Somali heritage observes quietly, arms crossed, the faint neon words “Free School” glowing in pink and blue on the rough brick wall behind him. Cables snake across the floor, and the air feels warm, charged with effort and hope. Photorealistic handheld 28mm, cinematic chiaroscuro contrast, textured realism of brick, light, and human concentration — a Marseille basement where coding becomes both rebellion and redemption. | I13: https://drive.google.com/file/d/1GRe-KNTsbZ5ht4cPBUqlWhABMo2cvnyg/view?usp=drive_link | J13: flux dev
A14: 84 | B14: 9 | C14: 10 | D14: A | E14: 1 | G14: Classe sous-marine des Calanques : Dans le parc national des Calanques, une station sous-marine futuriste sert de salle de classe aquatique. Descendus par un ascenseur depuis une plateforme en surface, des lycéens en combinaison souple évoluent dans un habitat sous l’eau où les murs vitrés donnent sur des posidonies et des bancs de poissons multicolores. Ils participent à un projet scientifique réel en surveillant la recolonisation des récifs artificiels posés après la surpêche du 21e siècle. Loin de la surface, ils apprennent l’écologie marine en symbiose avec le milieu (inspiré par le courant Cli-fi). | H14: Marseille, 2050. Beneath the clear blue waters of the Calanques, a marine biologist in full professional scuba gear hovers beside a young student, both connected by shimmering streams of bubbles rising toward the surface. They float calmly near a vibrant red gorgonian coral, its fan-like branches swaying in the gentle current. The teacher gestures slowly, a gloved hand tracing the coral’s structure, while the child — wearing a smaller dive tank and digital wrist display — leans closer to observe, eyes wide behind the mask. Around them, other students in scuba suits drift nearby, examining the seabed covered with seagrass and rocks dotted with sensors. Shafts of sunlight ripple through the water, casting gold patterns on their suits and the coral’s surface. Photorealistic cinematic realism, handheld 35mm, immersive underwater lighting, suspended sand particles, vibrant Mediterranean tones — a Marseille classroom of the future where learning happens in the living sea. | I14: https://drive.google.com/file/d/1GAnHl-oLUWLT24V_FZxUREu85xO9StH0/view?usp=drive_link | J14: flux dev
A15: 85 | B15: 9.5 | C15: 7.5 | D15: A | E15: 1 | G15: École nomade en voilier : Une goélette à énergie solaire fait office d’école itinérante en Méditerranée. À son bord, une classe de Marseille passe six mois à naviguer d’un port à l’autre. Le matin, cours de maths dans la salle de navigation en calculant la trajectoire vers Barcelone ; l’après-midi, les élèves apprennent l’histoire en visitant Carthage ou Athènes lors des escales. La vie en équipage développe leur sens des responsabilités et leur ouverture d’esprit, chaque nouvelle escale devenant une salle de classe à ciel ouvert (inspiré par le courant Hopepunk – aventure éducative). | H15: Marseille, 2050. A floating school-ship rests calmly at dock in the Vieux-Port, its sleek white structure moored beside the quays lined with cafés and palm trees. Through the wide glass windows of a classroom on the main deck, we see students seated at curved desks, their faces lit by the shimmer of sunlight reflecting off the harbor water. A teacher stands near a transparent smartboard, tracing lines on a digital map of the Mediterranean while the city skyline — Notre-Dame de la Garde, terracotta rooftops, cranes — glows in the background beyond the window. Inside, the atmosphere feels both nautical and scholarly: charts, model boats, and solar instruments hang along the walls, while the room rocks gently with the tide. Outside, a few passersby pause to watch this unusual school moored in the heart of Marseille. Photorealistic cinematic realism, handheld 35mm, warm coastal light, vivid reflections on glass and water, tactile textures of metal, fabric, and sea spray — a Marseille classroom docked between city and sea, where learning floats on the horizon. | I15: https://drive.google.com/file/d/1ZpH6yECACd6-FPK-Wl1Gr5b73R8fZ9ng/view?usp=drive_link | J15: flux dev
... A65: 88 | B65: 3.5 | C65: 9.5 | D65: B | E65: 1 | G65: Histoire en réalité virtuelle : Pour rendre l’histoire vivante, un professeur marseillais utilise la VR pour plonger ses élèves dans le passé. Un jour, la classe entière se retrouve à Massalia en 300 av. J.-C. : munis de casques, les élèves déambulent dans le port antique reconstruit en détail, croisent des Grecs et des Ligures, et assistent à une scène de marché antique. L’immersion est telle qu’en ôtant le casque, ils ont l’impression de revenir d’un voyage dans le temps. De retour dans la salle, le débat est passionné pour distinguer ce qu’ils ont vu de la réalité historique documentée (inspiré par la science-fiction historique). | H65: Marseille, 2050. In a digital archaeology classroom, a teacher of North African descent helps students remove VR headsets after visiting ancient Massalia. Dust motes float in projector light; models of ships and temples hover mid-air. Photorealistic 50mm handheld, deep texture and light, human wonder. | I65: https://drive.google.com/file/d/1dpXSCfvLJfHqBXhPv6vJ3QBQliX3-t7q/view?usp=drive_link | J65: flux dev
A66: 10 | B66: 6 | C66: 8 | D66: B | E66: 2 | F66: groupe n'a pas changé entre T1 et T2 | G66: Classes dans les grottes des Calanques : Pour échapper aux canicules estivales, certaines classes s’installent dans des grottes naturelles aménagées près de Sormiou. À la lueur de panneaux solaires LED, les élèves profitent de la fraîcheur souterraine pour étudier la géologie directement dans la roche calcaire qui les entoure. L’écho des grottes donne un caractère presque mystique aux leçons (inspiré par le courant Cli-fi d’adaptation climatique). | H66: Marseille, 2050. In a limestone cave classroom carved into the Calanques, a geology teacher stands before a group of students seated at makeshift desks of stone and metal, explaining the impact of extreme heat on rock formation. Behind them, a thick glass wall seals the cave from the world outside — a transparent barrier trembling under the glare. Beyond it, the sun burns white, the sky bleached and blinding. The soil outside smokes and ripples with heat distortion, air shimmering in dense waves like a desert mirage. Charred vegetation clings to cracked limestone, and condensation drips down the inner side of the glass. Inside, students watch in silence, their faces lit by both the orange of portable lamps and the blinding light beyond. Photorealistic handheld 28mm, extreme contrast between cool refuge and unbearable brightness, textures of glass, rock, and sweat — a cinematic vision of learning behind the last barrier to Marseille’s burning world. | I66: https://drive.google.com/file/d/1N9t-GV2AdjjqC_2IVcQVYeALd2U4LVDY/view?usp=drive_link | J66: flux dev
A67: 12 | B67: 1 | C67: 1 | D67: B | E67: 2 | G67: Bus scolaire amphibie : Dans un quartier côtier partiellement inondé, un vieux bus scolaire a été converti en navette amphibie. Chaque matin, il quitte la terre ferme et navigue sur les nouveaux canaux formés entre les immeubles pour récupérer les élèves. Ces derniers arrivent en classe après un trajet sur l’eau à travers la ville, illustration ingénieuse de la vie qui continue malgré la montée des eaux (inspiré par un imaginaire Cli-fi d’adaptation). | H67: Marseille, 2050. In the flooded district of L’Estaque, a yellow amphibious school bus floats gently between half-submerged buildings, its tires just visible beneath the waterline. The vehicle has been refitted with solar panels on the roof and a small rudder at the rear, gliding slowly through the new canals that once were city streets. Inside, a young teacher with dark curls and olive skin stands near the front, taking attendance on a transparent digital board while students of mixed origins peer through the wide open windows. Outside, reflections of balconies, traffic lights, and street signs shimmer beneath the surface, distorted by ripples. A few residents paddle past in small boats, waving as the school bus hums forward. Seagulls perch on flooded lampposts, and vines climb the sides of old buildings. The sunlight flashes across the water, painting dappled patterns onto the children’s faces. Photorealistic handheld 35mm, cinematic maritime tone, fine detail in water reflections, rusted architecture, and vibrant human movement — a serene vision of education afloat in the transformed heart of Marseille. | I67: https://drive.google.com/file/d/1ImFHoZv_Iu5PfAqIUClWPlMsAqGdDAd9/view?usp=drive_link | J67: flux dev
A68: 19 | B68: 5 | C68: 8 | D68: B | E68: 2 | G68: École-parc communautaire : Au parc Longchamp, un coin de verdure s’est mué en école en plein air où se retrouvent enfants du quartier et éducateurs. Les jardins botaniques servent de classe de sciences naturelles, le kiosque à musique accueille les cours de lecture à haute voix, et les pelouses font office de cour de récréation. L’environnement du parc, avec sa cascade et ses statues, stimule l’imaginaire des enfants tout en ouvrant l’école sur la cité (inspiré par le courant Solarpunk). | H68: Marseille, 2050. At Parc Longchamp, a literature teacher with brown skin and silver hoop earrings reads aloud under plane trees. Students of all shades sit cross-legged, notebooks open, wind flipping pages. Light dapples their faces and marble fountains. Photorealistic natural light, handheld 35mm, vivid textures of fabric, leaf, and laughter. | I68: https://drive.google.com/file/d/1IMVAaX0LTOiJ0Zo1Wmf8A1Xa2AM0Dc69/view?usp=drive_link | J68: flux dev
A69: 27 | B69: 9.5 | C69: 9 | D69: B | E69: 2 | G69: Exosquelette de sport | H69: Marseille, 2050. In the courtyard of a seaside high school near Sormiou, a physical education class plays basketball under the blazing Mediterranean sun. Among the players, a student wearing a lightweight exoskeleton leaps toward the hoop — metallic braces gleaming along his legs and spine, amplifying his jump with smooth hydraulic precision. His teammates, diverse in skin tones and energy, cheer and rush forward as the ball arcs through the air. The PE teacher, standing at the court’s edge with a whistle around her neck, watches proudly, clipboard in hand. The exoskeleton hums softly, its carbon frame reflecting the orange court markings and the sea’s blue glimmer beyond the fence. Beads of sweat, laughter, and motion fill the scene — a moment of inclusion powered by technology. Photorealistic handheld 35mm, cinematic Solarpunk realism, vivid midday light, sharp focus on metal, fabric, and skin — Marseille’s schools where every body can move, play, and soar. | I69: https://drive.google.com/file/d/1xKjcC3r5RyH-cH66JWb2TjfDBCAXPjps/view?usp=drive_link | J69: flux dev
A70: 32 | B70: 5 | C70: 7 | D70: B | E70: 2 | G70: Traduction | H70: Marseille, 2050. In the courtyard of an international lycée near La Major, two students — one French-Algerian, the other Korean — sit across from each other at a smart conversation table. Between them, a floating holographic sphere pulses softly with light each time one speaks, projecting instant subtitles in both French and Korean above the table’s surface. As the Korean student laughs and gestures, glowing Hangul characters ripple through the air, seamlessly mirrored by French text on the opposite side. The French student replies, her voice translated in real time through tiny earpieces that shimmer with blue LEDs. Around them, other pairs chat under the Mediterranean sun, voices blending into a calm digital murmur. The marble courtyard glows gold, the basilica’s shadow falling nearby. Photorealistic cinematic realism, handheld 35mm, warm daylight, crisp reflections on glass and skin — Marseille’s future schoolyard where language barriers dissolve in light. | I70: https://drive.google.com/file/d/1s0dB9fYxdXFUXAic7b27RJMy2GiqZxbi/view?usp=drive_link | J70: flux dev
A71: 36 | B71: 2.5 | C71: 8 | D71: B | E71: 2 | G71: Manuels holographiques : Les livres scolaires physiques ont quasiment disparu au profit de manuels holographiques et interactifs. En cours de sciences, un professeur fait apparaître au centre de la classe un cœur humain en 3D qui bat et réagit aux questions posées à voix haute. En littérature, les scènes d’un roman prennent vie en réalité augmentée autour des élèves. Ces supports immersifs transforment les apprentissages en expériences vivantes (inspiré par la science-fiction d’anticipation). | H71: Marseille, 2050. In a biology lab with open windows to the sea, a teacher with short locs adjusts a holographic heart model rotating mid-air. Students of mixed origins trace arteries with styluses. Red light pulses through the hologram, reflecting on their eyes and glass benches. Photorealistic cinematic glow, color contrast of blue daylight and red holographic tone. | I71: https://drive.google.com/file/d/13UquZY7-PvjzHDgsgE8YZgIgGEjT8mGr/view?usp=drive_link | J71: flux dev
A72: 39 | B72: 3 | C72: 4 | D72: B | E72: 2 | G72: Téléprésence d’élèves absents : Un élève hospitalisé à la Timone suit les cours depuis sa chambre grâce à un robot de téléprésence qui se déplace dans sa classe. Le robot, sur roulettes avec écran et caméra, permet à l’adolescent de voir le tableau, de participer aux discussions et même de sortir en récréation virtuelle avec ses amis. La frontière entre présence et distance s’estompe, assurant la continuité éducative même pour ceux qui ne peuvent physiquement être là (inspiré par la science-fiction d’anticipation). | H72: Marseille, 2050. Inside a Prado classroom, a telepresence robot rolls between rows. On its screen, a sick student smiles from home. The teacher — a middle-aged Black man — gestures toward it warmly, students wave back. The morning sun paints diagonal light bars across desks. Photorealistic 35mm, poetic everyday futurism. | I72: https://drive.google.com/file/d/19g54XFqTL892SxJURUGnckOtI22EWXYv/view?usp=drive_link | J72: flux dev
A73: 41 | B73: 6 | C73: 10 | D73: B | E73: 2 | G73: Projets citoyens au programme : Plutôt que de simples devoirs, les lycéens marseillais doivent réaliser chaque trimestre un projet concret pour leur quartier. L’un a coordonné la création d’un jardin partagé dans une friche des quartiers Nord, un autre a développé une appli pour recenser les fontaines d’eau potable de la ville. Ces projets, évalués par les habitants et les profs, remplacent les notes classiques et donnent du sens aux apprentissages théoriques (inspiré par le courant Hopepunk). | H73: Marseille, 2050. In a lush community garden in northern Marseille, a woman of Cape Verdean descent kneels beside a patch of rich soil, showing a group of children how to plant a seed. Her hands move slowly and deliberately, pressing the earth around the tiny sprout as the children — boys and girls of mixed backgrounds — watch closely, their faces lit by the low golden sun. Some hold small biodegradable pots, others dig with their fingers, laughing softly as they imitate her gesture. Around them, raised beds overflow with vegetables and flowers, and a solar-powered irrigation system hums gently in the background. The atmosphere is calm, purposeful, and full of warmth — learning through doing, rooted in care for the earth. Photorealistic cinematic realism, handheld 35mm, golden hour light, natural textures of soil, skin, and green life — a Marseille garden classroom where education grows from the ground up. | I73: https://drive.google.com/file/d/12Mz9KeJxCPlM2qz67Hmw9IBM49T5QKa3/view?usp=drive_link | J73: flux dev
A74: 47 | B74: 2 | C74: 7 | D74: B | E74: 2 | G74: Tutorat entre élèves : Une demi-journée par semaine, les rôles s'inversent au collège : les élèves plus âgés préparent des mini-leçons pour les plus jeunes, et les plus doués dans une matière aident ceux qui ont des difficultés. On voit ainsi un élève de 3ème animer un atelier d’anglais pour des 6ème, ou une experte en maths de 5ème expliquer une notion à des 4ème. Ce système valorise chacun et renforce la coopération plutôt que la compétition (inspiré par le courant Hopepunk – apprentissage collaboratif). | H74: Marseille, 2050. In a spacious, sunlit classroom arranged like an exam hall, rows of long tables fill the room, each shared by pairs of students — older teens mentoring younger children. In the foreground, a 19-year-old student sits beside an 8-year-old boy, leaning forward with calm focus as he explains a math exercise on the child’s tablet. The boy listens intently, his small hand tracing numbers on paper. Around them, in the soft blur of the background, dozens of similar pairs work together — teenagers guiding, encouraging, teaching. Sunlight pours through tall windows, glinting on the desks and illuminating the quiet energy of shared learning. Photorealistic cinematic realism, handheld 35mm, warm Mediterranean tones, wide composition with shallow depth of field — a Marseille classroom alive with mentorship and gentle cooperation. | I74: https://drive.google.com/file/d/1D0YlVvmnQu1an5WIpcZS4pz1x9UPUc3d/view?usp=drive_link | J74: flux dev
A75: 50 | B75: 4 | C75: 7 | D75: B | E75: 2 | G75: Artisanat et high-tech main dans la main : Un nouveau lycée d’un genre hybride a ouvert à Marseille, où chaque élève apprend un métier manuel en parallèle des compétences numériques. On y voit un groupe forger un couteau à la forge provençale le matin puis coder une imprimante 3D l’après-midi pour en reproduire le manche en bioplastique. Valoriser autant la menuiserie traditionnelle que la robotique dans un même cursus redonne ses lettres de noblesse aux savoir-faire concrets (inspiré par le courant Solarpunk). | H75: Marseille, 2050. Inside a bright carpentry workshop flooded with sunlight, a teacher wearing advanced kinetic gloves controls a futuristic laser-sculpting machine enclosed in transparent glass. Inside the chamber, a block of wood slowly transforms into a perfect sphere, the glowing red laser beam tracing its contours in fluid motion, layer by layer. The teacher’s hand gestures guide the process in real time, every movement echoed by the machine’s precise response. Around the workbench, students in goggles and aprons watch in absorbed silence — some leaning closer to catch the detail, others filming the transformation on their tablets. Behind them, shelves of handcrafted wooden models and digital tools line the sunlit walls, bridging past and future craft. Photorealistic cinematic realism, handheld 35mm, warm tones of wood, glass, and sunlight — a Marseille workshop where artisans sculpt tradition through the gestures of tomorrow. | I75: https://drive.google.com/file/d/1tSTzXjNaPUNRChNu_KXo5zS2_ya0dndH/view?usp=drive_link | J75: flux dev
A76: 60 | B76: 7.5 | C76: 10 | D76: B | E76: 2 | G76: Nature professeur : Une fois par semaine, la classe n’a pas lieu en classe mais sur le terrain. Accompagnés de leurs professeurs, des collégiens partent randonner dans le massif de l’Étoile pour un cours de géologie in situ, ou plongent dans les Calanques avec masque et tuba pour observer les posidonies en cours de biologie marine. À la campagne, un agriculteur local leur fait découvrir la permaculture pendant que leur enseignant de sciences prend des notes avec eux. Cette école du dehors ancre les savoirs dans le réel et renforce le lien à la nature (inspiré par le courant Solarpunk). | H76: Marseille, 2050. In the Massif de l’Étoile hills, a geology teacher with tanned skin points at fossil layers. Students squat in dust, recording observations on slates. The light is sharp, colors sun-bleached. A mix of laughter, cicadas, and wind fills the air. Photorealistic 35mm handheld, earthy tones, tactile fieldwork realism. | I76: https://drive.google.com/file/d/1ZKNFi19ZoD83MlC0Y9QvLCM4pLP6fjDi/view?usp=drive_link | J76: flux dev
A77: 63 | B77: 4.5 | C77: 10 | D77: B | E77: 2 | G77: Formation tout au long de la vie : La ville de Marseille, en partenariat avec l’État, a mis en place un crédit formation universel pour ses habitants. À tout âge, chacun peut prendre une "année sabbatique éducative" rémunérée pour apprendre quelque chose de nouveau. On croise ainsi en cours du soir à la fac des trentenaires découvrant la biologie marine, des quinquagénaires se formant aux énergies solaires, ou des retraités s’initiant à la réalité virtuelle pour voyager autrement. Cette soif de savoir intergénérationnelle redynamise la cité phocéenne (inspiré par une utopie sociale). | H77: Marseille, 2050. Inside a sun-drenched amphitheater at Aix-Marseille University, rows of students lean over sleek digital desks that glow faintly with holographic notes. Among them sits an elderly woman with silver hair and dark skin, her lined face illuminated by the same blue light as her younger classmates. She listens intently as a professor gestures before a transparent board, formulas and diagrams floating mid-air. Around her, students in their twenties — diverse, curious — glance with respect, sharing quiet smiles. Some wear AR glasses; others type on flexible tablets. The atmosphere hums with intergenerational energy — no hierarchy, just shared learning. Outside the panoramic windows, the Mediterranean glimmers beyond solar canopies and rooftop gardens. Photorealistic cinematic realism, handheld 50mm, warm daylight tones, tactile textures of skin, glass, and light reflections — Marseille’s university of 2050, where every age learns side by side. | I77: https://drive.google.com/file/d/1lK1Pxi01PCMvEdYxcZLlF-1QumOYauaE/view?usp=drive_link | J77: flux dev
A78: 68 | B78: 6.5 | C78: 7 | D78: B | E78: 2 | G78: Retraités-tuteurs à l’école : Un programme municipal recrute des seniors bénévoles pour accompagner les élèves. Dans une école primaire du Camas, chaque retraité parraine un élève : deux soirs par semaine, ils se retrouvent à la bibliothèque pour lire ensemble, faire les devoirs, ou simplement discuter de la vie. Les enfants gagnent un mentor affectueux et patient; les aînés, un sentiment d’utilité et de transmission. Ce mélange des générations ranime l’esprit de village au cœur de la ville (inspiré par le courant Hopepunk). | H78: Marseille, 2050. In a small Camas library, a teenage girl helps an elderly man with handwriting practice. The teacher watches from behind a dusty shelf. Afternoon light slants across their faces, ink and paper gleaming. Photorealistic 50mm handheld, cinematic realism with poetic intimacy. | I78: https://drive.google.com/file/d/175k2iWpcxPtwrwANs4lwjSd0ku6lhqmW/view?usp=drive_link | J78: flux dev
... A95: 60 | B95: 8 | C95: 9 | D95: B | E95: 3 | G95: Nature professeur : Une fois par semaine, la classe n’a pas lieu en classe mais sur le terrain. Accompagnés de leurs professeurs, des collégiens partent randonner dans le massif de l’Étoile pour un cours de géologie in situ, ou plongent dans les Calanques avec masque et tuba pour observer les posidonies en cours de biologie marine. À la campagne, un agriculteur local leur fait découvrir la permaculture pendant que leur enseignant de sciences prend des notes avec eux. Cette école du dehors ancre les savoirs dans le réel et renforce le lien à la nature (inspiré par le courant Solarpunk). | H95: Marseille, 2050. In the Massif de l’Étoile hills, a geology teacher with tanned skin points at fossil layers. Students squat in dust, recording observations on slates. The light is sharp, colors sun-bleached. A mix of laughter, cicadas, and wind fills the air. Photorealistic 35mm handheld, earthy tones, tactile fieldwork realism. | I95: https://drive.google.com/file/d/1ZKNFi19ZoD83MlC0Y9QvLCM4pLP6fjDi/view?usp=drive_link | J95: flux dev
D96: B | E96: 3 | F96: 63 enlevée entre T2 et T3
A97: 68 | B97: 6 | C97: 7 | D97: B | E97: 3 | G97: Retraités-tuteurs à l’école : Un programme municipal recrute des seniors bénévoles pour accompagner les élèves. Dans une école primaire du Camas, chaque retraité parraine un élève : deux soirs par semaine, ils se retrouvent à la bibliothèque pour lire ensemble, faire les devoirs, ou simplement discuter de la vie. Les enfants gagnent un mentor affectueux et patient; les aînés, un sentiment d’utilité et de transmission. Ce mélange des générations ranime l’esprit de village au cœur de la ville (inspiré par le courant Hopepunk). | H97: Marseille, 2050. In a small Camas library, a teenage girl helps an elderly man with handwriting practice. The teacher watches from behind a dusty shelf. Afternoon light slants across their faces, ink and paper gleaming. Photorealistic 50mm handheld, cinematic realism with poetic intimacy. | I97: https://drive.google.com/file/d/175k2iWpcxPtwrwANs4lwjSd0ku6lhqmW/view?usp=drive_link | J97: flux dev
A98: 70 | B98: 7.5 | C98: 8 | D98: B | E98: 3 | G98: Echange international facilité | H98: Marseille, 2050. Inside the Saint-Charles train station, bathed in bright Mediterranean light filtering through the glass roof, a young student with a backpack stands before a large interactive map table, his hand hovering over glowing destinations — Lisbon, Dakar, Athens, Montréal. The map pulses softly with lines of light connecting cities in real time, labeled Student Exchange Network. Behind him, a few travelers hurry past sleek magnetic trains gleaming in the station’s curve. A rail attendant in a navy vest watches with a friendly smile as the boy confirms his choice, the word “Authorized – Planetary Student Mobility” appearing briefly in holographic text. His backpack is light but worn, a small patch reading Université Marseille. Sunlight glints off the polished floor, blending motion and anticipation. Photorealistic cinematic realism, handheld 35mm, rich travel textures of glass, steel, fabric, and skin — Marseille as a gateway where learning begins with a journey. | I98: https://drive.google.com/file/d/1XRTqszkjtPRwqm_86WxFzN7y-5ezVh73/view?usp=drive_link | J98: flux dev
A99: 79 | B99: 5.5 | C99: 5.5 | D99: B | E99: 3 | G99: La ville apprenante : Marseille est devenue un immense terrain d’apprentissage à ciel ouvert. Un cours d’histoire se déroule dans les ruelles du Panier où les élèves, guidés par une appli, doivent retrouver des indices du passé médiéval de la ville. En sciences, la classe investit le Muséum d’Histoire Naturelle du Palais Longchamp pour étudier des fossiles régionaux, puis part aux îles du Frioul observer les goélands et comprendre l’écosystème insulaire. Les devoirs ressemblent à des enquêtes urbaines où la ville elle-même fait office de manuel vivant (inspiré par le courant Hopepunk). | H99: Marseille, 2050. In a sunlit alley of Le Panier, two schoolchildren crouch beside an old stone wall, studying a digital tablet glowing in their hands. On the screen, a simple treasure map shows a few blocky outlines of buildings and a red X marking the spot, the interface bright against the dusty pavement. One child — a girl with curly hair — traces the route with her finger, while the other — a boy in a striped T-shirt — scans the surroundings, comparing the map to the real street. Behind them, laundry sways above faded shutters, and a stray cat slips past a graffiti-covered door. Photorealistic cinematic realism, handheld 35mm, warm Mediterranean light, shallow depth of field, strong contrast between the cool digital glow and sunlit stone — a Marseille alley turned into a classroom for discovery and play. | I99: https://drive.google.com/file/d/1TCfJXk9B28RWx1nfpLxixUu2EwnDQN67/view?usp=drive_link | J99: flux dev
A100: 81 | B100: 1 | C100: 8 | D100: B | E100: 3 | G100: École hackée underground : Dans les sous-sols d’une usine abandonnée de la zone de la Joliette, un collectif de jeunes hackers a créé sa propre école officieuse. L’ambiance y est cyberpunk : néons colorés, murs couverts de code binaire en graffiti et écrans recyclés branchés sur le réseau. On y enseigne le code, la cybersécurité et la fabrication d’objets libres en dehors de tout cadre officiel. Les connaissances circulent librement, et les membres du collectif piratent les bases de données académiques pour démocratiser le savoir, dans un esprit rebelle mais solidaire (inspiré par le courant Cyberpunk). | H100: Marseille, 2050. In a dimly lit La Joliette basement, the air hums softly with the rhythm of typing. At the front, a young woman wearing a light-colored veil works intently, her face illuminated by the blue glow of her screen as lines of code scroll in reflection. Around her, other students — men and women without veils — sit at scattered desks, focused, their faces half-lit by flickering monitors. At the back of the room, a computer science teacher of Somali heritage observes quietly, arms crossed, the faint neon words “Free School” glowing in pink and blue on the rough brick wall behind him. Cables snake across the floor, and the air feels warm, charged with effort and hope. Photorealistic handheld 28mm, cinematic chiaroscuro contrast, textured realism of brick, light, and human concentration — a Marseille basement where coding becomes both rebellion and redemption. | I100: https://drive.google.com/file/d/1GRe-KNTsbZ5ht4cPBUqlWhABMo2cvnyg/view?usp=drive_link | J100: flux dev
A101: 83 | B101: 1 | C101: 9.5 | D101: B | E101: 3 | G101: Échange scolaire sur Mars : Marseille s’est jumelée avec la première colonie humaine sur Mars. Chaque année, quelques lycéens marseillais sélectionnés s’envolent pour la planète rouge dans le cadre d’un échange scolaire extraordinaire. En scaphandre dans un dôme pressurisé, ils suivent les cours de géologie martienne le matin et partagent l’après-midi en visiocasque leurs découvertes avec leurs camarades restés sur Terre. Voir de jeunes Marseillais faire un exposé depuis la surface de Mars inspire toute une génération à rêver plus grand que la Terre (inspiré par la science-fiction spatiale). | H101: Mars, 2050. Inside a fully transparent classroom dome nestled in the middle of the Martian desert, a small group of students in lightweight red-and-white space suits sits at curved desks beneath a glass ceiling. The walls and roof form a seamless bubble, perfectly clear yet shimmering slightly under the thin atmosphere. Outside, the rust-red dunes stretch endlessly, scattered with research modules and solar arrays glinting under the pale sun. Inside, a teacher in a flexible pressure suit stands beside a holographic screen showing a live Zoom call with a classroom in Marseille — bright blue Mediterranean light and children waving on Earth fill the display. One Martian student proudly lifts a small green plant sprout grown in local soil, holding it up for their Earth peers to see, while another takes notes on a transparent tablet. Light refracts through the dome, casting soft orange highlights across faces, tables, and floor. Photorealistic cinematic realism, handheld 35mm, crisp red and amber tones against cool Earth blues, detailed reflections on glass — a serene vision of education beyond worlds, where Marseille meets Mars under the same sun. | I101: https://drive.google.com/file/d/1h56VBP1qsjQnxXNGS864y5frBUsy-pSr/view?usp=drive_link | J101: flux dev
A102: 87 | B102: 3.5 | C102: 8 | D102: B | E102: 3 | G102: Club nano-technologie : Dans un collège, un club scientifique d’après-cours donne aux élèves accès à la nanotechnologie. Avec un microscope à force atomique, ils programment des essaims de nano-robots pour qu’ils nettoient l’eau d’un aquarium pollué. D’autres conçoivent des nanoparticules qui, ajoutées à la peinture des bancs publics, les empêchent de surchauffer en été. Ce qui relevait de la science-fiction est devenu une activité ludique et écologique pour ces jeunes innovateurs (inspiré par la science-fiction futuriste sur les nanotechnologies). | H102: Marseille, 2050. In a Vieux-Port nano-lab, a teacher with short gray hair demonstrates a micro-robot test. Students lean close, the holographic data casting blue light on their faces. Through the window, sails glint in the distance. Photorealistic handheld 50mm, deep contrast, tactile realism of human curiosity. | I102: https://drive.google.com/file/d/1fHxTi8Bq-nA6q8dSoTcyRv8p4dEkEZ3Y/view?usp=drive_link | J102: flux dev
A103: 88 | B103: 3.5 | C103: 9.5 | D103: B | E103: 3 | G103: Histoire en réalité virtuelle : Pour rendre l’histoire vivante, un professeur marseillais utilise la VR pour plonger ses élèves dans le passé. Un jour, la classe entière se retrouve à Massalia en 300 av. J.-C. : munis de casques, les élèves déambulent dans le port antique reconstruit en détail, croisent des Grecs et des Ligures, et assistent à une scène de marché antique. L’immersion est telle qu’en ôtant le casque, ils ont l’impression de revenir d’un voyage dans le temps. De retour dans la salle, le débat est passionné pour distinguer ce qu’ils ont vu de la réalité historique documentée (inspiré par la science-fiction historique). | H103: Marseille, 2050. In a digital archaeology classroom, a teacher of North African descent helps students remove VR headsets after visiting ancient Massalia. Dust motes float in projector light; models of ships and temples hover mid-air. Photorealistic 50mm handheld, deep texture and light, human wonder. | I103: https://drive.google.com/file/d/1dpXSCfvLJfHqBXhPv6vJ3QBQliX3-t7q/view?usp=drive_link | J103: flux dev
A104: 9 | B104: 8.5 | C104: 4 | D104: C | E104: 1 | G104: Tour d’arcologie éducative : Une tour-école verticale domine la skyline marseillaise. Sur des dizaines d’étages autosuffisants, on trouve potagers hydroponiques, ateliers de robotique, serre tropicale et observatoire astronomique. Les élèves prennent des ascenseurs-jardins pour passer de la classe de littérature en bas, baignée de lumière naturelle, au laboratoire de chimie tout en haut avec vue sur toute la ville (inspiré par le courant Solarpunk). | H104: Marseille, 2050. Inside a towering vertical glass school at La Joliette, students move between subjects in a seamless flow of learning. In the foreground, a transparent elevator glides upward through a sunlit atrium filled with greenery. Inside, a teacher stands beside students, pointing toward two visible classrooms stacked above one another — the chemistry lab on the upper level, where colored liquids bubble in clear tubes, and the robotics workshop just below, where mechanical arms and student-built drones gleam under soft light. The walls and ceiling are entirely transparent, revealing the skyline, solar panels, and reflections of the harbor below. Students step out of the elevator mid-frame, some entering robotics, others rising toward chemistry. Photorealistic cinematic realism, handheld 35mm, warm Mediterranean brightness, reflections on glass, detailed human and mechanical textures — an architectural vision of Marseille’s transparent, interconnected education of 2050. | I104: https://drive.google.com/file/d/1MYQymWLreUpEhTiwThsgXOqHA_JQxhBI/view?usp=drive_link | J104: flux dev
A105: 22 | B105: 9.5 | C105: 5 | D105: C | E105: 1 | G105: Enquête dans la ville | H105: Marseille, 2050. On the Corniche Kennedy, a history teacher of North African descent gestures toward AR ruins overlaying the rocks. A Black student sketches; a red-haired classmate records notes. Sea spray blurs the edges. Photorealistic street-photo realism, high-contrast Mediterranean light. | I105: https://drive.google.com/file/d/1R3kylnvAD23hjccwzGCXjkBXUEntgoVe/view?usp=drive_link | J105: flux dev
...

Sheet data_num
A1: n° | B1: Marseille (x) | C1: Futur (y) | D1: Table | E1: Tour | F1: Remarque | G1: idée | H1: prompt original | I1: image (URL) | J1: model | K1: Valide (1 = oui) | L1: zoom haut-droit (1 = oui) | M1: distance à l'idéal (10/10)
A2: 1 | B2: 4 | C2: 7 | D2: environnement | E2: 1 | F2: par rapport au précédent atelier, les élèves ont bien compris les deux axes | G2: Élève-Sonde : Lecture Directe du Vivant Solaire. Inspiré par le Solarpunk, le scénario montre une étudiante agenouillée sur un toit-jardin urbain. Elle utilise une sonde numérique alimentée par les panneaux solaires voisins pour lire l'état du sol et de l'air ambiant. L'éducation sort des murs pour se lier à la gestion concrète de l'oasis de biodiversité, formant les jeunes aux métiers de la résilience climatique. | H2: A focused young adult student, wearing practical field gear, kneels on a sunny, green rooftop classroom. She is meticulously inserting a rugged, high-tech probe into a planter box filled with drought-resistant Mediterranean plants (rosemary, thyme, succulents). Behind her, rows of visible solar panels catch the sun, and the background shows the edge of the rooftop garden with other students and a teacher in soft focus. Her action, centered in the frame, is the direct measurement of soil moisture and composition, with a small, attached screen displaying real-time data overlaid with holographic graphs. The scene explicitly combines solar energy, biodiversity, and practical education. Realistic photography, 35mm sensor, cinematic light, ultra-realistic detail. | I2: https://drive.google.com/file/d/1brfp_3ww49nn4tc4Gxkt_n8pqQlDtJH5/view?usp=drive_link | J2: nano banana | K2: {=IF((B2:B49<>"")*(C2:C49<>""),1,)} -> 1 | L2: {=IF(K2:K49="",,IF((B2:B49>5)*(C2:C49>5),1,0))} -> 0 | M2: {=IF(A2:A49="",, IFERROR( SQRT( (10 - IFERROR(VALEUR(B2:B49), B2:B49))^2 + (10 - IFERROR(VALEUR(C2:C49), C2:C49))^2 ), "" ) )} -> 6.7082039
A3: 2 | D3: environnement | E3: 2 | F3: pas de notes | G3: Classes solaires sous les pins parasols Dans les calanques, des étudiants apprennent l'écologie marine sous des voiles photovoltaïques tissées, leurs tablettes transparentes alimentées par le soleil projetant des données sur l'eau. L'énergie solaire alimente aussi des pompes pour un système d'aquaponie éducatif intégré aux rochers. | H3: A candid photograph captures a group of diverse students in an open-air classroom on a Mediterranean coast, under large, translucent solar-panel canopies shaped like sails. They are sitting on wooden benches carved into the rock, looking at transparent tablets that display marine life data. In the center, a teacher points to a small aquaponics system built into the cliff, with water flowing through sun-powered glass tubes. The sun is setting over the sea. The style is naturalistic and warm. | I3: https://drive.google.com/file/d/12HGPBPqNgAOQJ5tMlZ7AN2XvPaiezzYW/view?usp=drive_link | J3: nano banana | M3: 14.142136
A4: 3 | D4: environnement | E4: 3 | F4: pas de notes | G4: Restauration récifale par analyse spectrale immersive. Équipés de recycleurs et de gants de données haptiques, des étudiants réalisent l'analyse spectrale de colonies de coraux en détresse. Ce cours de bio-littératie sur site participe activement à la régénération des écosystèmes côtiers. | H4: A documentary-style underwater photograph shows a marine biology student, wearing a compact rebreather and a complex haptic data glove, carefully touching a piece of bleached coral on a Mediterranean reef. A waterproof, translucent holographic screen floats next to their hand, projecting real-time spectral data graphs and colorful diagnostic overlays onto the coral structure. Sunlight filters down through clear blue waters. Other student divers are visible in the background carrying similar equipment. The gear looks rugged and experimental. Film grain. | I4: https://drive.google.com/file/d/1d6aqW_lTwONn_Vzg7zkzyb3oB71FAc-o/view?usp=drive_link | J4: nano banana | M4: 14.142136
A5: 4 | B5: 6 | C5: 9 | D5: environnement | E5: 4 | G5: Leçon d'anatomie marine par la lumière tangible. Sous une pergola bioclimatique face à la mer, une étudiante manipule d'un geste précis l'hologramme complexe d'une posidonie géante. L'interface gestuelle permet de disséquer virtuellement la plante pour comprendre sa résilience au réchauffement climatique. | H5: A documentary-style photograph taken with a 35mm lens. A young woman, a university student, stands on a terraced coastal outdoor laboratory overlooking the Mediterranean sea. She wears sleek, sensors-embedded haptic gloves. Her hands are raised, actively manipulating a large, translucent, glowing green and blue holographic projection of a complex Posidonia oceanica seagrass root system that floats in the air before her. Other students are in the blurred background. The sunlight is bright, golden hour. The architecture is stone and wood, integrated with plants. | I5: https://drive.google.com/file/d/1Qj5Cx_NoOyusSk0sZFQDkl-kafsWrCSV/view?usp=drive_link | J5: nano banana | K5: 1 | L5: 1 | M5: 4.1231056
A6: 5 | B6: 5 | C6: 8 | D6: environnement | E6: 5 | G6: Échange Silencieux, Connexion Profonde/ Dans un monde ou on s'échange des connaissances via un appareille connecte comme le Bluetooth sans besoin de parler que deviens les échanges humain ? | H6: A futuristic, realistic photograph of a group of students in a sleek, minimalist learning space with warm, natural light. They are all wearing small, almost imperceptible neural interface devices on their temples. One student in the foreground is looking intently at another, their hands slightly raised as if in a gesture of shared understanding, even though no words are being spoken. The background shows subtle holographic projections of data and knowledge floating in the air. | I6: https://drive.google.com/file/d/1EOEXx-FE2I00HTdtwmKWBV37237WOQoY/view?usp=drive_link | J6: nano banana | K6: 1 | L6: 0 | M6: 5.3851648
A7: 6 | B7: 7 | C7: 8 | D7: environnement | E7: 6 | G7: L'Archipel des Esprits, Apprendre par l'Action Collective. Dans un monde ou l'échange instantané de données libère le temps de l'apprentissage théorique pour l'appliquer. Les étudiants se rassemblent dans d'anciens jardins-écoles méditerranéens, où ils utilisent leur savoir commun pour réparer la biodiversité locale. Leur connexion neurale remplace les longues discussions par une intelligence collective haptique focalisée sur le geste, recréant un lien social fondamental basé sur la co-création. | H7: Ultra-realistic contemporary photograph, 35mm sensor, cinematic lighting. A young adult, central in the foreground, with warm Mediterranean sunlight illuminating their face. They are standing in a lush, rewilded rooftop garden with terracotta pots and solar panels visible in the background. They are wearing a small, subtle ear-worn device. The person is actively grafting a plant, one hand touching a glowing section of the plant where a holographic data-stream (knowledge of plant biology) is subtly overlaid, indicating a non-verbal knowledge transfer. The atmosphere is serene and deeply focused. | I7: https://drive.google.com/file/d/1U7f1XvGmZg9ZfLRJ62MCXWRSYBUAcZgc/view?usp=drive_link | J7: nano banana | K7: 1 | L7: 1 | M7: 3.6055513
A8: 7 | B8: 3 | C8: 10 | D8: environnement | E8: 7 | F8: pas d'image | G8: Rencontre Inattendue, Leçon Sauvage. Dans un avenir où la technologie a brisé les barrières de la communication, les humains et les animaux partagent un dialogue continu. La jeune femme de la réserve méditerranéenne s'est approchée du cerf, utilisant son traducteur vocal, et ils échangent, le cerf lui transmettant calmement des savoirs ancestraux sur les rythmes de la nature et l'équilibre des écosystèmes. | H8: A realistic photograph of a young woman in an olive grove, gently speaking to a majestic stag. She holds a small, elegant bio-luminescent device near her mouth, which glows softly, indicating it's actively translating. The stag, looking directly at her, has a serene and understanding expression, its head slightly tilted as if listening intently and about to respond. The atmosphere is one of profound connection and shared knowledge, bathed in warm, dappled sunlight. | J8: nano banana | K8: 1 | L8: 0 | M8: 7
